Workbook

Sheet Suivi
A1: # | B1: Catégorie | C1: Organisme | D1: Région | E1: E-mail | F1: Source / fiabilité | G1: Angle | H1: Objet du mail | I1: Statut | J1: Date d'envoi | K1: Relance prévue (J+5 ouvré) | L1: Date de relance | M1: Réponse | N1: Lien obtenu (URL) | O1: Notes
A2: 1 | B2: Média | C2: Maddyness | D2: National | E2: redaction@maddyness.com | F2: Officiel (page Facebook de Maddyness) | G2: Baromètre des prix | H2: 83 % des logiciels de caisse cachent leurs prix (étude TPE 2027) | I2: Relancé | J2: 46314 | K2: =IF(J2="","",WORKDAY(J2+4,1)) -> 46321 | L2: 46321 | O2: Relancé
A3: 2 | B3: Média | C3: Le Blog du Dirigeant | D3: National | E3: contact@leblogdudirigeant.com | F3: Officiel (page contact, indexée il y a environ 3 ans) | G3: Baromètre des prix | H3: Une donnée inédite pour vos lecteurs dirigeants de TPE | I3: Répondu | J3: 46314 | K3: =IF(J3="","",WORKDAY(J3+4,1)) -> 46321 | M3: Oui | O3: 19/10 : propose un article sponsorisé (500 € HT fourni, 650 € HT rédigé). Décliné le 19/10 ; proposé un extrait de données gratuit. Pas de relance.
A4: 3 | B4: Média | C4: Compta-Online | D4: National | E4: forum@compta-online.com | F4: Fournie par toi | G4: Simulateurs | H4: Des simulateurs gratuits à intégrer pour vos lecteurs (TVA, charges, IK) | I4: Relancé | J4: 46314 | K4: =IF(J4="","",WORKDAY(J4+4,1)) -> 46321 | L4: 46321 | O4: Relancé
A5: 4 | B5: Média | C5: Portail Auto-Entrepreneur | D5: National | E5: contact@portail-autoentrepreneur.fr | F5: Fournie par toi | G5: Simulateurs charges + TVA | H5: Un simulateur de charges gratuit pour vos lecteurs auto-entrepreneurs | I5: Relancé | J5: 46314 | K5: =IF(J5="","",WORKDAY(J5+4,1)) -> 46321 | L5: 46321 | O5: Relancé
A6: 5 | B6: Média | C6: Journal du Freelance | D6: National | E6: tavor.management@gmail.com | F6: Fournie par toi | G6: Calculateur TJM | H6: Un calculateur de TJM gratuit pour vos lecteurs freelances | I6: Relancé | J6: 46314 | K6: =IF(J6="","",WORKDAY(J6+4,1)) -> 46321 | L6: 46321 | O6: Relancé
A7: 6 | B7: Expert-comptable | C7: les-experts-comptables.fr | D7: National | E7: (page Contact du site) | F7: Article cité : /ressources/facturation-electronique-auto-entrepreneur/ | G7: Simulateur seuil TVA | H7: Un simulateur de seuil de TVA gratuit pour compléter votre guide auto-entrepreneur | I7: Pas de réponse | K7: =IF(J7="","",WORKDAY(J7+4,1)) | O7: Brouillon supprimé le 19/10 (pas d’adresse publique) : passer par le formulaire du site si besoin
A8: 7 | B8: Fédération | C8: FNAE | D8: National | E8: contact@fnae.fr | F8: Fournie par toi | G8: Guide + check-list | H8: Une ressource gratuite pour vos adhérents auto-entrepreneurs | I8: Relancé | J8: 46314 | K8: =IF(J8="","",WORKDAY(J8+4,1)) -> 46321 | L8: 46321 | O8: Relancé
A9: 8 | B9: Fédération | C9: Union des auto-entrepreneurs | D9: National | E9: contact@union-auto-entrepreneurs.com | F9: Fournie par toi | G9: Guide + check-list | H9: Une ressource gratuite pour les auto-entrepreneurs que vous accompagnez | I9: Relancé | J9: 46314 | K9: =IF(J9="","",WORKDAY(J9+4,1)) -> 46321 | L9: 46321 | O9: Relancé
A10: 9 | B10: CCI | C10: CCI Paris Île-de-France (Val-d'Oise) | D10: Île-de-France | E10: creation95@cci-paris-idf.fr | F10: Tiers (valparisis.fr) | G10: Check-list + simulateurs | H10: Un outil gratuit pour vos porteurs de projet (facture électronique 2027) | I10: Envoyé | J10: 46318 | K10: =IF(J10="","",WORKDAY(J10+4,1)) -> 46323 | O10: Relance prévue le 28/10/2026
A11: 10 | B11: CCI | C11: CCI Bretagne | D11: Bretagne | E11: ccir@bretagne.cci.fr | F11: Officiel ancien (douane.gouv.fr), à vérifier | G11: Check-list + simulateurs | H11: Un outil gratuit pour vos porteurs de projet (facture électronique 2027) | I11: Relancé | J11: 46314 | K11: =IF(J11="","",WORKDAY(J11+4,1)) -> 46321 | L11: 46321 | O11: Relancé
A12: 11 | B12: CCI | C12: CCI Hauts-de-France | D12: Hauts-de-France | E12: ccideregion@hautsdefrance.cci.fr | F12: Tiers (document CCI repris) | G12: Check-list + simulateurs | H12: Un outil gratuit pour vos porteurs de projet (facture électronique 2027) | I12: Adresse invalide | J12: 46318 | K12: =IF(J12="","",WORKDAY(J12+4,1)) -> 46323 | O12: 23/10 : rebond, message bloqué par le serveur de CCI Hauts-de-France. Pas de relance.
A13: 12 | B13: CCI | C13: CCI Ouest Normandie | D13: Normandie | E13: cci@normandie.cci.fr | F13: Tiers (annuaire-administration.com) | G13: Check-list + simulateurs | H13: Un outil gratuit pour vos porteurs de projet (facture électronique 2027) | I13: Adresse invalide | J13: 46318 | K13: =IF(J13="","",WORKDAY(J13+4,1)) -> 46323 | O13: 23/10 : rebond, message bloqué par le serveur de CCI Ouest Normandie. Pas de relance.
A14: 13 | B14: CCI | C14: CCI Portes de Normandie | D14: Normandie | E14: info-eure@normandie.cci.fr | F14: Tiers (annuaire-administration.com) | G14: Check-list + simulateurs | H14: Un outil gratuit pour vos porteurs de projet (facture électronique 2027) | I14: Envoyé | J14: 46318 | K14: =IF(J14="","",WORKDAY(J14+4,1)) -> 46323 | O14: Relance prévue le 28/10/2026
A15: 14 | B15: CCI | C15: CCI Nouvelle-Aquitaine | D15: Nouvelle-Aquitaine | E15: contact@nouvelle-aquitaine.cci.fr | F15: Tiers (annuaire-administration.com) | G15: Check-list + simulateurs | H15: Un outil gratuit pour vos porteurs de projet (facture électronique 2027) | I15: Envoyé | J15: 46318 | K15: =IF(J15="","",WORKDAY(J15+4,1)) -> 46323 | O15: Relance prévue le 28/10/2026
A16: 15 | B16: CCI | C16: CCI Nantes St-Nazaire (création-reprise) | D16: Pays de la Loire | E16: conseil-creation-reprise@44.cci.fr | F16: Tiers, source non relevée : à vérifier | G16: Check-list + simulateurs | H16: Un outil gratuit pour vos porteurs de projet (facture électronique 2027) | I16: Envoyé | J16: 46318 | K16: =IF(J16="","",WORKDAY(J16+4,1)) -> 46323 | O16: Relance prévue le 28/10/2026
A17: 16 | B17: CMA | C17: CMA Val-d'Oise | D17: Île-de-France | E17: eco@cma95.fr | F17: Tiers (valparisis.fr) | G17: Check-list artisans | H17: Facture électronique 2027 : une check-list gratuite pour les artisans | I17: Adresse invalide | J17: 46318 | K17: =IF(J17="","",WORKDAY(J17+4,1)) -> 46323 | O17: 23/10 : rebond, message bloqué par le serveur de CMA Val-d'Oise. Pas de relance.
A18: 17 | B18: CMA | C18: CMA Auvergne-Rhône-Alpes | D18: Auvergne-Rhône-Alpes | E18: contact@crma-auvergnerhonealpes.fr | F18: Tiers, 2018 : peut être obsolète | G18: Check-list artisans | H18: Facture électronique 2027 : une check-list gratuite pour les artisans | I18: Envoyé | J18: 46318 | K18: =IF(J18="","",WORKDAY(J18+4,1)) -> 46323 | O18: 23/10 : réponse automatique, l'adresse n'est plus suivie : contacter la CMA départementale. Relance prévue le 28/10/2026.
A19: 18 | B19: CMA | C19: CMA Côte-d'Or | D19: Bourgogne-Franche-Comté | E19: accueil-s21@artisanat-bfc.fr | F19: Tiers (annuaire-administration.com) | G19: Check-list artisans | H19: Facture électronique 2027 : une check-list gratuite pour les artisans | I19: Envoyé | J19: 46318 | K19: =IF(J19="","",WORKDAY(J19+4,1)) -> 46323 | O19: Relance prévue le 28/10/2026
A20: 19 | B20: CMA | C20: CMA Morbihan | D20: Bretagne | E20: accueil@cma-morbihan.fr | F20: Tiers (annuaire-administration.com) | G20: Check-list artisans | H20: Facture électronique 2027 : une check-list gratuite pour les artisans | I20: Envoyé | J20: 46318 | K20: =IF(J20="","",WORKDAY(J20+4,1)) -> 46323 | O20: Relance prévue le 28/10/2026
A21: 20 | B21: CMA | C21: CMA Loiret | D21: Centre-Val de Loire | E21: contact@cma45.fr | F21: Tiers (annuaire-administration.com) | G21: Check-list artisans | H21: Facture électronique 2027 : une check-list gratuite pour les artisans | I21: Brouillon prêt | K21: =IF(J21="","",WORKDAY(J21+4,1)) | O21: Envoi conseillé : jour 6
A22: 21 | B22: CMA | C22: CMA Alsace | D22: Grand Est | E22: cma@cm-alsace.fr | F22: Tiers (strasbourg-europe.eu) | G22: Check-list artisans | H22: Facture électronique 2027 : une check-list gratuite pour les artisans | I22: Brouillon prêt | K22: =IF(J22="","",WORKDAY(J22+4,1)) | O22: Envoi conseillé : jour 6
A23: 22 | B23: CMA | C23: CMA Hauts-de-France | D23: Hauts-de-France | E23: contact@cma-hautsdefrance.fr | F23: Tiers (annuaire-administration.com) | G23: Check-list artisans | H23: Facture électronique 2027 : une check-list gratuite pour les artisans | I23: Brouillon prêt | K23: =IF(J23="","",WORKDAY(J23+4,1)) | O23: Envoi conseillé : jour 6
A24: 23 | B24: CMA | C24: CMA Charente | D24: Nouvelle-Aquitaine | E24: 16-eco@cma-nouvelleaquitaine.fr | F24: Tiers (document de commune) | G24: Check-list artisans | H24: Facture électronique 2027 : une check-list gratuite pour les artisans | I24: Brouillon prêt | K24: =IF(J24="","",WORKDAY(J24+4,1)) | O24: Envoi conseillé : jour 6
A25: 24 | B25: CMA | C25: CMA Vienne | D25: Nouvelle-Aquitaine | E25: 86-cma-info@cma-nouvelleaquitaine.fr | F25: Tiers (lavienne86.fr) | G25: Check-list artisans | H25: Facture électronique 2027 : une check-list gratuite pour les artisans | I25: Brouillon prêt | K25: =IF(J25="","",WORKDAY(J25+4,1)) | O25: Envoi conseillé : jour 6
A26: 25 | B26: CMA | C26: CMA Loire-Atlantique | D26: Pays de la Loire | E26: entreprises44@cma-paysdelaloire.fr | F26: Officiel, à revérifier | G26: Check-list artisans | H26: Facture électronique 2027 : une check-list gratuite pour les artisans | I26: Relancé | J26: 46314 | K26: =IF(J26="","",WORKDAY(J26+4,1)) -> 46321 | L26: 46321 | O26: Relancé
A27: 26 | B27: CMA | C27: CMA Alpes-Maritimes | D27: PACA | E27: contact06@cmar-paca.fr | F27: Tiers (annuaire-administration.com) | G27: Check-list artisans | H27: Facture électronique 2027 : une check-list gratuite pour les artisans | I27: Brouillon prêt | K27: =IF(J27="","",WORKDAY(J27+4,1)) | O27: Envoi conseillé : jour 6
A28: 27 | B28: Réseau | C28: BGE Réseau (national) | D28: National | E28: accueil@bge.asso.fr | F28: Officiel (bge.asso.fr, 2024) | G28: Simulateurs + check-list | H28: Des outils gratuits pour les entrepreneurs que vous accompagnez | I28: Adresse invalide | J28: 46314 | K28: =IF(J28="","",WORKDAY(J28+4,1)) -> 46321 | O28: Réponse auto 19/10 : boîte plus relevée. Pas de relance. Viser les BGE régionales.
A29: 28 | B29: CCI | C29: CCI Réunion (conseil entreprise) | D29: La Réunion | E29: conseilentreprise@reunion.cci.fr | F29: Officiel (page d’environ 5 ans) | G29: Check-list + simulateurs | H29: Un outil gratuit pour vos porteurs de projet (facture électronique 2027) | I29: Relancé | J29: 46314 | K29: =IF(J29="","",WORKDAY(J29+4,1)) -> 46321 | L29: 46321 | O29: Relancé
A30: 29 | B30: CCI | C30: CCI Loiret | D30: Centre-Val de Loire | E30: entreprendre@loiret.cci.fr | F30: Officiel (centre.cci.fr) | G30: Check-list + simulateurs | H30: Un outil gratuit pour vos porteurs de projet (facture électronique 2027) | I30: Relancé | J30: 46314 | K30: =IF(J30="","",WORKDAY(J30+4,1)) -> 46321 | L30: 46321 | O30: Relancé
A31: 30 | B31: CCI | C31: CCI Cher, Espace Entreprendre | D31: Centre-Val de Loire | E31: espace-entreprendre@cher.cci.fr | F31: Officiel (centre.cci.fr) | G31: Check-list + simulateurs | H31: Un outil gratuit pour vos porteurs de projet (facture électronique 2027) | I31: Relancé | J31: 46314 | K31: =IF(J31="","",WORKDAY(J31+4,1)) -> 46321 | L31: 46321 | O31: Relancé
A32: 31 | B32: CCI | C32: CCI Indre | D32: Centre-Val de Loire | E32: entreprendre@indre.cci.fr | F32: Officiel (centre.cci.fr) | G32: Check-list + simulateurs | H32: Un outil gratuit pour vos porteurs de projet (facture électronique 2027) | I32: Relancé | J32: 46315 | K32: =IF(J32="","",WORKDAY(J32+4,1)) -> 46321 | L32: 46321 | O32: Relancé
A33: 32 | B33: CCI | C33: CCI Loir-et-Cher | D33: Centre-Val de Loire | E33: entreprendre@41.cci.fr | F33: Officiel (centre.cci.fr) | G33: Check-list + simulateurs | H33: Un outil gratuit pour vos porteurs de projet (facture électronique 2027) | I33: Relancé | J33: 46315 | K33: =IF(J33="","",WORKDAY(J33+4,1)) -> 46321 | L33: 46321 | O33: Relancé
A34: 33 | B34: CCI | C34: CCI Vendée, Espace Création | D34: Pays de la Loire | E34: espace.creation@vendee.cci.fr | F34: Officiel (paysdelaloire.cci.fr) | G34: Check-list + simulateurs | H34: Un outil gratuit pour vos porteurs de projet (facture électronique 2027) | I34: Relancé | J34: 46315 | K34: =IF(J34="","",WORKDAY(J34+4,1)) -> 46321 | L34: 46321 | O34: Relancé
A35: 34 | B35: CCI | C35: CCI Tarn | D35: Occitanie | E35: monprojetaveclacci@tarn.cci.fr | F35: Officiel (tarn.cci.fr) | G35: Check-list + simulateurs | H35: Un outil gratuit pour vos porteurs de projet (facture électronique 2027) | I35: Relancé | J35: 46315 | K35: =IF(J35="","",WORKDAY(J35+4,1)) -> 46321 | L35: 46321 | O35: Relancé
A36: 35 | B36: CCI | C36: CCI Alpes-de-Haute-Provence | D36: PACA | E36: creation@digne.cci.fr | F36: Officiel (digne.cci.fr) | G36: Check-list + simulateurs | H36: Un outil gratuit pour vos porteurs de projet (facture électronique 2027) | I36: Relancé | J36: 46315 | K36: =IF(J36="","",WORKDAY(J36+4,1)) -> 46321 | L36: 46321 | O36: Relancé
A37: 36 | B37: CCI | C37: CCI Métropole de Bourgogne, Espace Entreprendre | D37: Bourgogne-Franche-Comté | E37: espace.entreprendre@mdb.cci.fr | F37: Officiel (metropoledebourgogne.cci.fr) | G37: Check-list + simulateurs | H37: Un outil gratuit pour vos porteurs de projet (facture électronique 2027) | I37: Relancé | J37: 46315 | K37: =IF(J37="","",WORKDAY(J37+4,1)) -> 46321 | L37: 46321 | O37: Relancé
A38: 37 | B38: CCI | C38: CCI Lyon Métropole | D38: Auvergne-Rhône-Alpes | E38: infos@lyon-metropole.cci.fr | F38: Officiel (contact général) | G38: Check-list + simulateurs | H38: Un outil gratuit pour vos porteurs de projet (facture électronique 2027) | I38: Relancé | J38: 46315 | K38: =IF(J38="","",WORKDAY(J38+4,1)) -> 46321 | L38: 46321 | O38: Relancé
A39: 38 | B39: CCI | C39: CCI PACA | D39: PACA | E39: information@paca.cci.fr | F39: Officiel (contact général) | G39: Check-list + simulateurs | H39: Un outil gratuit pour vos porteurs de projet (facture électronique 2027) | I39: Relancé | J39: 46315 | K39: =IF(J39="","",WORKDAY(J39+4,1)) -> 46321 | L39: 46321 | O39: Relancé
A40: 39 | B40: CMA | C40: CMA Pyrénées-Orientales | D40: Occitanie | E40: contact@cma66.fr | F40: Officiel (annuaire service-public.gouv.fr) | G40: Check-list artisans | H40: Facture électronique 2027 : une check-list gratuite pour les artisans | I40: Relancé | J40: 46315 | K40: =IF(J40="","",WORKDAY(J40+4,1)) -> 46321 | L40: 46321 | O40: Relancé
...

Sheet Statistiques
A1: Tableau de bord de la prospection
A3: Contacts avec adresse | B3: =COUNTIF(Suivi!$E$2:$E$200,"*@*") -> 95
A4: Brouillons prêts | B4: =COUNTIF(Suivi!$I$2:$I$200,"Brouillon prêt") -> 31
A5: Envoyés (y compris relancés, répondus, liens) | B5: =COUNTIF(Suivi!$I$2:$I$200,"Envoyé")+COUNTIF(Suivi!$I$2:$I$200,"Relancé")+COUNTIF(Suivi!$I$2:$I$200,"Répondu")+COUNTIF(Suivi!$I$2:$I$200,"Lien obtenu")+COUNTIF(Suivi!$I$2:$I$200,"Refus")+COUNTIF(Suivi!$I$2:$I$200,"Pas de réponse") -> 57
A6: Relancés | B6: =COUNTIF(Suivi!$I$2:$I$200,"Relancé") -> 32
A7: Réponses reçues | B7: =COUNTIF(Suivi!$M$2:$M$200,"Oui") -> 2
A8: Liens obtenus | B8: =COUNTIF(Suivi!$I$2:$I$200,"Lien obtenu") -> 0
A9: Refus | B9: =COUNTIF(Suivi!$I$2:$I$200,"Refus") -> 1
A10: Adresses invalides (rebonds) | B10: =COUNTIF(Suivi!$I$2:$I$200,"Adresse invalide") -> 8
A11: Taux de réponse | B11: =IFERROR(B7/B5,0) -> 0.035087719
A12: Taux d'obtention de lien | B12: =IFERROR(B8/B5,0) -> 0
A13: Relances dues aujourd'hui | B13: =COUNTIFS(Suivi!$K$2:$K$200,"<="&TODAY(),Suivi!$I$2:$I$200,"Envoyé",Suivi!$L$2:$L$200,"") -> 0
A15: Repères habituels : 5 à 15 % de réponses, quelques liens pour 50 envois.
A17: Par catégorie
A18: Catégorie | B18: Contacts | C18: Envoyés | D18: Liens
A19: Média | B19: =COUNTIF(Suivi!$B$2:$B$200,A19) -> 9 | C19: =COUNTIFS(Suivi!$B$2:$B$200,A19,Suivi!$J$2:$J$200,"<>") -> 8 | D19: =COUNTIFS(Suivi!$B$2:$B$200,A19,Suivi!$I$2:$I$200,"Lien obtenu") -> 0
A20: Expert-comptable | B20: =COUNTIF(Suivi!$B$2:$B$200,A20) -> 3 | C20: =COUNTIFS(Suivi!$B$2:$B$200,A20,Suivi!$J$2:$J$200,"<>") -> 1 | D20: =COUNTIFS(Suivi!$B$2:$B$200,A20,Suivi!$I$2:$I$200,"Lien obtenu") -> 0
A21: Fédération | B21: =COUNTIF(Suivi!$B$2:$B$200,A21) -> 5 | C21: =COUNTIFS(Suivi!$B$2:$B$200,A21,Suivi!$J$2:$J$200,"<>") -> 5 | D21: =COUNTIFS(Suivi!$B$2:$B$200,A21,Suivi!$I$2:$I$200,"Lien obtenu") -> 0
A22: CCI | B22: =COUNTIF(Suivi!$B$2:$B$200,A22) -> 18 | C22: =COUNTIFS(Suivi!$B$2:$B$200,A22,Suivi!$J$2:$J$200,"<>") -> 18 | D22: =COUNTIFS(Suivi!$B$2:$B$200,A22,Suivi!$I$2:$I$200,"Lien obtenu") -> 0
A23: CMA | B23: =COUNTIF(Suivi!$B$2:$B$200,A23) -> 20 | C23: =COUNTIFS(Suivi!$B$2:$B$200,A23,Suivi!$J$2:$J$200,"<>") -> 13 | D23: =COUNTIFS(Suivi!$B$2:$B$200,A23,Suivi!$I$2:$I$200,"Lien obtenu") -> 0
A24: Réseau | B24: =COUNTIF(Suivi!$B$2:$B$200,A24) -> 9 | C24: =COUNTIFS(Suivi!$B$2:$B$200,A24,Suivi!$J$2:$J$200,"<>") -> 1 | D24: =COUNTIFS(Suivi!$B$2:$B$200,A24,Suivi!$I$2:$I$200,"Lien obtenu") -> 0
A25: Initiative | B25: =COUNTIF(Suivi!$B$2:$B$200,A25) -> 10 | C25: =COUNTIFS(Suivi!$B$2:$B$200,A25,Suivi!$J$2:$J$200,"<>") -> 3 | D25: =COUNTIFS(Suivi!$B$2:$B$200,A25,Suivi!$I$2:$I$200,"Lien obtenu") -> 0
A26: Réseau Entreprendre | B26: =COUNTIF(Suivi!$B$2:$B$200,A26) -> 8 | C26: =COUNTIFS(Suivi!$B$2:$B$200,A26,Suivi!$J$2:$J$200,"<>") -> 7 | D26: =COUNTIFS(Suivi!$B$2:$B$200,A26,Suivi!$I$2:$I$200,"Lien obtenu") -> 0
A27: Couveuse / CAE | B27: =COUNTIF(Suivi!$B$2:$B$200,A27) -> 11 | C27: =COUNTIFS(Suivi!$B$2:$B$200,A27,Suivi!$J$2:$J$200,"<>") -> 5 | D27: =COUNTIFS(Suivi!$B$2:$B$200,A27,Suivi!$I$2:$I$200,"Lien obtenu") -> 0
A28: Association | B28: =COUNTIF(Suivi!$B$2:$B$200,A28) -> 3 | C28: =COUNTIFS(Suivi!$B$2:$B$200,A28,Suivi!$J$2:$J$200,"<>") -> 3 | D28: =COUNTIFS(Suivi!$B$2:$B$200,A28,Suivi!$I$2:$I$200,"Lien obtenu") -> 0
A29: Total | B29: =SUM(B19:B28) -> 96 | C29: =SUM(C19:C28) -> 64 | D29: =SUM(D19:D28) -> 0

Sheet Mode d'emploi
A1: Mode d'emploi du suivi
A3: Cellules à remplir : les colonnes sur fond jaune clair de l'onglet Suivi (Statut, dates, Réponse, Lien, Notes).
A4: Les brouillons correspondants sont dans Gmail (compte logimalin@gmail.com), dossier Brouillons, avec le même objet.
A6: 1. Le jour de l'envoi : envoie le brouillon, puis passe le Statut à « Envoyé » et saisis la Date d'envoi.
A7: 2. La colonne « Relance prévue » se calcule seule (J+5) et devient orange quand la relance est due.
A8: 3. Relance une seule fois, en deux lignes, puis passe le Statut à « Relancé » et saisis la Date de relance.
A9: 4. À la réponse : Réponse = Oui. Si un lien vers le site est publié, Statut = « Lien obtenu » et colle l'URL.
A10: 5. Mail revenu en erreur : Statut = « Adresse invalide », et cherche la page contact du site.
A12: Règles d'envoi : 10 à 15 mails par jour au maximum, un destinataire par mail (jamais de copie groupée),
A13: une seule relance, et toujours la ligne « répondez STOP » pour se désinscrire.
A14: Fiabilité des adresses : « Tiers » = trouvée dans un annuaire ou un document externe, à vérifier si le mail revient.
A15: Colonne Notes : « Envoi conseillé : jour N » répartit les envois à 13 par jour, adresses officielles d'abord.
A16: Lignes vides en bas de l'onglet Suivi : prêtes pour les nouveaux contacts.
